Workbook

Sheet Resumo
A1: Base do solver: defesa contra RFI (ChipEV, 40bb)
A2: Cada spot é o hero contra o open da posição imediatamente à direita. Fonte: prints do GTO Wizard enviados pelo usuário.
A4: Spot | B4: Raise (3bet) | C4: All-in | D4: Call | E4: 3bet total | F4: Defende no total | G4: Fold | H4: % do 3bet na defesa | I4: Obs.
A5: HJ vs LJ | B5: 0.079 | C5: 0 | D5: 0.055 | E5: =B5+C5 -> 0.079 | F5: =E5+D5 -> 0.134 | G5: =1-F5 -> 0.866 | H5: =E5/F5 -> 0.58955224 | I5: Raise 3x
A6: CO vs HJ | B6: 0.088 | C6: 0 | D6: 0.08 | E6: =B6+C6 -> 0.088 | F6: =E6+D6 -> 0.168 | G6: =1-F6 -> 0.832 | H6: =E6/F6 -> 0.52380952 | I6: Raise 3x
A7: BTN vs CO | B7: 0.098 | C7: 0 | D7: 0.151 | E7: =B7+C7 -> 0.098 | F7: =E7+D7 -> 0.249 | G7: =1-F7 -> 0.751 | H7: =E7/F7 -> 0.3935743 | I7: Raise 3x
A8: SB vs BTN | B8: 0.13 | C8: 0.041 | D8: 0.116 | E8: =B8+C8 -> 0.171 | F8: =E8+D8 -> 0.287 | G8: =1-F8 -> 0.713 | H8: =E8/F8 -> 0.59581882 | I8: Raise 3,5x + all-in
A10: Notas
A11: Células em azul são números lidos dos prints do solver (Raise, All-in e Call mostrados na tela). Em preto, fórmulas.
A12: O fold calculado (100% − defende) pode diferir de 0,1 ponto do fold da tela por arredondamento.
A13: O 3bet quase não cresce com a posição (7,9% → 9,8% do HJ ao BTN), enquanto o call vai de 5,5% para 15,1%.
A14: No SB o 3bet domina a defesa. No BTN o call domina.
A15: Os spots aqui são uma base: muitos dos seus spots reais serão contra openers mais cedo (range mais curto).

Sheet CallOpen_vs_Base
A1: Seu call open contra a base do solver
A2: Valores do painel de evolução (S1 a S4) e metas do coach. Preencha a S5 e os 3bets nas células amarelas.
A4: Posição | B4: S1 | C4: S2 | D4: S3 | E4: S4 | F4: S5 | G4: Meta mín | H4: Meta máx | I4: Meta S4 | J4: Base solver (call) | K4: S4 − base | L4: S4 − meta S4 | M4: Status S4 vs meta
A5: HJ | B5: 0.09 | C5: 0.077 | D5: 0.077 | E5: 0.045 | G5: 0.08 | H5: 0.09 | I5: 0.08 | J5: =Resumo!D5 -> 0.055 | K5: =E5-J5 -> -0.01 | L5: =E5-I5 -> -0.035 | M5: =IF(E5<G5,"Abaixo da meta",IF(E5>H5,"Acima da meta","Na meta")) -> Abaixo da meta
A6: CO | B6: 0.11 | C6: 0.098 | D6: 0.095 | E6: 0.083 | G6: 0.12 | H6: 0.15 | I6: 0.11 | J6: =Resumo!D6 -> 0.08 | K6: =E6-J6 -> 0.003 | L6: =E6-I6 -> -0.027 | M6: =IF(E6<G6,"Abaixo da meta",IF(E6>H6,"Acima da meta","Na meta")) -> Abaixo da meta
A7: BTN | B7: 0.12 | C7: 0.13 | D7: 0.074 | E7: 0.086 | G7: 0.16 | H7: 0.19 | I7: 0.15 | J7: =Resumo!D7 -> 0.151 | K7: =E7-J7 -> -0.065 | L7: =E7-I7 -> -0.064 | M7: =IF(E7<G7,"Abaixo da meta",IF(E7>H7,"Acima da meta","Na meta")) -> Abaixo da meta
A8: SB | B8: 0.12 | C8: 0.12 | D8: 0.12 | E8: 0.11 | G8: 0.13 | H8: 0.16 | I8: 0.13 | J8: =Resumo!D8 -> 0.116 | K8: =E8-J8 -> -0.006 | L8: =E8-I8 -> -0.02 | M8: =IF(E8<G8,"Abaixo da meta",IF(E8>H8,"Acima da meta","Na meta")) -> Abaixo da meta
A10: 3bet por posição (preencha)
A11: Posição | B11: S1 | C11: S2 | D11: S3 | E11: S4 | F11: S5
A12: HJ
A13: CO
A14: BTN
A15: SB
A17: Call + 3bet (defesa total, fórmula)
A18: Posição | B18: S1 | C18: S2 | D18: S3 | E18: S4 | F18: S5
A19: HJ | B19: =IF(AND(ISNUMBER(B5),ISNUMBER(B12)),B5+B12,"") | C19: =IF(AND(ISNUMBER(C5),ISNUMBER(C12)),C5+C12,"") | D19: =IF(AND(ISNUMBER(D5),ISNUMBER(D12)),D5+D12,"") | E19: =IF(AND(ISNUMBER(E5),ISNUMBER(E12)),E5+E12,"") | F19: =IF(AND(ISNUMBER(F5),ISNUMBER(F12)),F5+F12,"")
A20: CO | B20: =IF(AND(ISNUMBER(B6),ISNUMBER(B13)),B6+B13,"") | C20: =IF(AND(ISNUMBER(C6),ISNUMBER(C13)),C6+C13,"") | D20: =IF(AND(ISNUMBER(D6),ISNUMBER(D13)),D6+D13,"") | E20: =IF(AND(ISNUMBER(E6),ISNUMBER(E13)),E6+E13,"") | F20: =IF(AND(ISNUMBER(F6),ISNUMBER(F13)),F6+F13,"")
A21: BTN | B21: =IF(AND(ISNUMBER(B7),ISNUMBER(B14)),B7+B14,"") | C21: =IF(AND(ISNUMBER(C7),ISNUMBER(C14)),C7+C14,"") | D21: =IF(AND(ISNUMBER(D7),ISNUMBER(D14)),D7+D14,"") | E21: =IF(AND(ISNUMBER(E7),ISNUMBER(E14)),E7+E14,"") | F21: =IF(AND(ISNUMBER(F7),ISNUMBER(F14)),F7+F14,"")
A22: SB | B22: =IF(AND(ISNUMBER(B8),ISNUMBER(B15)),B8+B15,"") | C22: =IF(AND(ISNUMBER(C8),ISNUMBER(C15)),C8+C15,"") | D22: =IF(AND(ISNUMBER(D8),ISNUMBER(D15)),D8+D15,"") | E22: =IF(AND(ISNUMBER(E8),ISNUMBER(E15)),E8+E15,"") | F22: =IF(AND(ISNUMBER(F8),ISNUMBER(F15)),F8+F15,"")
A24: Legenda
A25: Amarelo = células para você preencher (S5 e 3bets). Azul = números digitados. Preto = fórmulas. Verde = vínculo com outra aba.
A26: Exemplo de preenchimento: 3bet do HJ na S4 = 4,1% (digite 4,1% ou 0,041). O resultado aparece na linha "Call + 3bet".
A27: Metas do coach: HJ 8–9%, CO 12–15%, BTN 16–19%, SB 13–16%. "Meta S4" é a meta intermediária definida para a semana 4.
A28: A base do solver é um teto: o seu stat soma todos os openers, e contra posições mais cedo o call esperado é menor.

Sheet Padroes
A1: Padrões entre call e 3bet no solver
A2: Lidos dos grids dos prints: % das combinações de cada família de mãos que dão 3bet ou call.
A4: Família | B4: HJ 3bet | C4: HJ Call | D4: CO 3bet | E4: CO Call | F4: BTN 3bet | G4: BTN Call | H4: SB 3bet | I4: SB Call
A5: Pares | B5: 0.44 | C5: 0.27 | D5: 0.45 | E5: 0.38 | F5: 0.45 | G5: 0.55 | H5: 0.74 | I5: 0.26
A6: Suited | B6: 0.09 | C6: 0.12 | D6: 0.12 | E6: 0.17 | F6: 0.11 | G6: 0.31 | H6: 0.18 | I6: 0.29
A7: Offsuit | B7: 0.05 | C7: 0.01 | D7: 0.05 | E7: 0.03 | F7: 0.06 | G7: 0.07 | H7: 0.12 | I7: 0.05
A9: Mãos que continuam e mãos que estão nos dois (call e 3bet)
A10: Spot | B10: Mãos que continuam | C10: Mistas (3bet e call) | D10: % mistas
A11: HJ vs LJ | B11: 33 | C11: 14 | D11: =C11/B11 -> 0.42424242
A12: CO vs HJ | B12: 41 | C12: 17 | D12: =C12/B12 -> 0.41463415
A13: BTN vs CO | B13: 58 | C13: 19 | D13: =C13/B13 -> 0.32758621
A14: SB vs BTN | B14: 65 | C14: 25 | D14: =C14/B14 -> 0.38461538
A16: Padrões encontrados
A17: 1. O 3bet fica quase estável de HJ a BTN (7,9% → 9,8%) e o call triplica (5,5% → 15,1%): defender mais contra opens tardios é, em grande parte, call.
A18: 2. Cerca de 40% das mãos que continuam estão nos dois: são as de força média (AQo, KQo, AJo, 99–77, JTs, T9s, A9s, A8s, A5s). No HJ, o AQo é 44% call e 56% 3bet.
A19: 3. Offsuit quase nunca é call puro nas posições cedo (HJ: 5% 3bet e 1% call das combinações offsuit): AQo, AJo, ATo e KQo são 3bet ou fold.
A20: 4. O 3bet tem valor (AA a JJ, AK, AQs) e bloqueadores que pagam mal (A5s, A6s, K9s, Q9s e, no BTN, A4s a A2s e K8s a K6s).
A21: 5. Call puro: AJs, ATs, KQs, KJs, KTs, QJs, QTs, pares médios e baixos e, só em posição tardia, os suited connectors (T9s, 98s, 87s, 76s).
A22: 6. Pares: o 3bet fica em ~45% dos pares de HJ a BTN e o call sobe de 27% para 55%. No SB, 74% dos pares vão de 3bet.
A24: Valores em azul foram lidos pela cor de cada célula nos prints (3bet/all-in em laranja ou vermelho, call em verde-água). Margem de leitura de poucos pontos.

Sheet Maos_por_spot
A1: As 169 mãos em cada spot (3bet, call e continua)
A2: Frequências lidas dos grids pela cor da célula, arredondadas para 5%. Fold = o que sobra. Exatos da tela: AQo no HJ (56% 3bet / 44% call), AKo no BTN (100% 3bet), AA no CO (94/6), AQo no SB (100% 3bet).
A4: Mão | B4: HJ 3bet | C4: HJ Call | D4: HJ Continua | E4: HJ Ação | F4: CO 3bet | G4: CO Call | H4: CO Continua | I4: CO Ação | J4: BTN 3bet | K4: BTN Call | L4: BTN Continua | M4: BTN Ação | N4: SB 3bet | O4: SB Call | P4: SB Continua | Q4: SB Ação
A5: AA | B5: 1 | C5: 0 | D5: =B5+C5 -> 1 | E5: =IF(D5<0.2,"Fold",IF(AND(B5>=0.2,C5>=0.2),"3bet/call",IF(B5>=C5,"3bet","Call"))) -> 3bet | F5: 0.94 | G5: 0.06 | H5: =F5+G5 -> 1 | I5: =IF(H5<0.2,"Fold",IF(AND(F5>=0.2,G5>=0.2),"3bet/call",IF(F5>=G5,"3bet","Call"))) -> 3bet | J5: 1 | K5: 0 | L5: =J5+K5 -> 1 | M5: =IF(L5<0.2,"Fold",IF(AND(J5>=0.2,K5>=0.2),"3bet/call",IF(J5>=K5,"3bet","Call"))) -> 3bet | N5: 1 | O5: 0 | P5: =N5+O5 -> 1 | Q5: =IF(P5<0.2,"Fold",IF(AND(N5>=0.2,O5>=0.2),"3bet/call",IF(N5>=O5,"3bet","Call"))) -> 3bet
A6: AKs | B6: 1 | C6: 0 | D6: =B6+C6 -> 1 | E6: =IF(D6<0.2,"Fold",IF(AND(B6>=0.2,C6>=0.2),"3bet/call",IF(B6>=C6,"3bet","Call"))) -> 3bet | F6: 1 | G6: 0 | H6: =F6+G6 -> 1 | I6: =IF(H6<0.2,"Fold",IF(AND(F6>=0.2,G6>=0.2),"3bet/call",IF(F6>=G6,"3bet","Call"))) -> 3bet | J6: 1 | K6: 0 | L6: =J6+K6 -> 1 | M6: =IF(L6<0.2,"Fold",IF(AND(J6>=0.2,K6>=0.2),"3bet/call",IF(J6>=K6,"3bet","Call"))) -> 3bet | N6: 1 | O6: 0 | P6: =N6+O6 -> 1 | Q6: =IF(P6<0.2,"Fold",IF(AND(N6>=0.2,O6>=0.2),"3bet/call",IF(N6>=O6,"3bet","Call"))) -> 3bet
A7: AQs | B7: 0 | C7: 1 | D7: =B7+C7 -> 1 | E7: =IF(D7<0.2,"Fold",IF(AND(B7>=0.2,C7>=0.2),"3bet/call",IF(B7>=C7,"3bet","Call"))) -> Call | F7: 0.75 | G7: 0.25 | H7: =F7+G7 -> 1 | I7: =IF(H7<0.2,"Fold",IF(AND(F7>=0.2,G7>=0.2),"3bet/call",IF(F7>=G7,"3bet","Call"))) -> 3bet/call | J7: 1 | K7: 0 | L7: =J7+K7 -> 1 | M7: =IF(L7<0.2,"Fold",IF(AND(J7>=0.2,K7>=0.2),"3bet/call",IF(J7>=K7,"3bet","Call"))) -> 3bet | N7: 1 | O7: 0 | P7: =N7+O7 -> 1 | Q7: =IF(P7<0.2,"Fold",IF(AND(N7>=0.2,O7>=0.2),"3bet/call",IF(N7>=O7,"3bet","Call"))) -> 3bet
A8: AJs | B8: 0 | C8: 1 | D8: =B8+C8 -> 1 | E8: =IF(D8<0.2,"Fold",IF(AND(B8>=0.2,C8>=0.2),"3bet/call",IF(B8>=C8,"3bet","Call"))) -> Call | F8: 0 | G8: 1 | H8: =F8+G8 -> 1 | I8: =IF(H8<0.2,"Fold",IF(AND(F8>=0.2,G8>=0.2),"3bet/call",IF(F8>=G8,"3bet","Call"))) -> Call | J8: 0 | K8: 1 | L8: =J8+K8 -> 1 | M8: =IF(L8<0.2,"Fold",IF(AND(J8>=0.2,K8>=0.2),"3bet/call",IF(J8>=K8,"3bet","Call"))) -> Call | N8: 1 | O8: 0 | P8: =N8+O8 -> 1 | Q8: =IF(P8<0.2,"Fold",IF(AND(N8>=0.2,O8>=0.2),"3bet/call",IF(N8>=O8,"3bet","Call"))) -> 3bet
A9: ATs | B9: 0 | C9: 1 | D9: =B9+C9 -> 1 | E9: =IF(D9<0.2,"Fold",IF(AND(B9>=0.2,C9>=0.2),"3bet/call",IF(B9>=C9,"3bet","Call"))) -> Call | F9: 0 | G9: 1 | H9: =F9+G9 -> 1 | I9: =IF(H9<0.2,"Fold",IF(AND(F9>=0.2,G9>=0.2),"3bet/call",IF(F9>=G9,"3bet","Call"))) -> Call | J9: 0 | K9: 1 | L9: =J9+K9 -> 1 | M9: =IF(L9<0.2,"Fold",IF(AND(J9>=0.2,K9>=0.2),"3bet/call",IF(J9>=K9,"3bet","Call"))) -> Call | N9: 1 | O9: 0 | P9: =N9+O9 -> 1 | Q9: =IF(P9<0.2,"Fold",IF(AND(N9>=0.2,O9>=0.2),"3bet/call",IF(N9>=O9,"3bet","Call"))) -> 3bet
A10: A9s | B10: 0.45 | C10: 0.55 | D10: =B10+C10 -> 1 | E10: =IF(D10<0.2,"Fold",IF(AND(B10>=0.2,C10>=0.2),"3bet/call",IF(B10>=C10,"3bet","Call"))) -> 3bet/call | F10: 0.25 | G10: 0.75 | H10: =F10+G10 -> 1 | I10: =IF(H10<0.2,"Fold",IF(AND(F10>=0.2,G10>=0.2),"3bet/call",IF(F10>=G10,"3bet","Call"))) -> 3bet/call | J10: 0 | K10: 1 | L10: =J10+K10 -> 1 | M10: =IF(L10<0.2,"Fold",IF(AND(J10>=0.2,K10>=0.2),"3bet/call",IF(J10>=K10,"3bet","Call"))) -> Call | N10: 0 | O10: 1 | P10: =N10+O10 -> 1 | Q10: =IF(P10<0.2,"Fold",IF(AND(N10>=0.2,O10>=0.2),"3bet/call",IF(N10>=O10,"3bet","Call"))) -> Call
A11: A8s | B11: 0.75 | C11: 0.25 | D11: =B11+C11 -> 1 | E11: =IF(D11<0.2,"Fold",IF(AND(B11>=0.2,C11>=0.2),"3bet/call",IF(B11>=C11,"3bet","Call"))) -> 3bet/call | F11: 0.35 | G11: 0.65 | H11: =F11+G11 -> 1 | I11: =IF(H11<0.2,"Fold",IF(AND(F11>=0.2,G11>=0.2),"3bet/call",IF(F11>=G11,"3bet","Call"))) -> 3bet/call | J11: 0 | K11: 1 | L11: =J11+K11 -> 1 | M11: =IF(L11<0.2,"Fold",IF(AND(J11>=0.2,K11>=0.2),"3bet/call",IF(J11>=K11,"3bet","Call"))) -> Call | N11: 0 | O11: 1 | P11: =N11+O11 -> 1 | Q11: =IF(P11<0.2,"Fold",IF(AND(N11>=0.2,O11>=0.2),"3bet/call",IF(N11>=O11,"3bet","Call"))) -> Call
A12: A7s | B12: 0.1 | C12: 0 | D12: =B12+C12 -> 0.1 | E12: =IF(D12<0.2,"Fold",IF(AND(B12>=0.2,C12>=0.2),"3bet/call",IF(B12>=C12,"3bet","Call"))) -> Fold | F12: 0.6 | G12: 0.4 | H12: =F12+G12 -> 1 | I12: =IF(H12<0.2,"Fold",IF(AND(F12>=0.2,G12>=0.2),"3bet/call",IF(F12>=G12,"3bet","Call"))) -> 3bet/call | J12: 0 | K12: 1 | L12: =J12+K12 -> 1 | M12: =IF(L12<0.2,"Fold",IF(AND(J12>=0.2,K12>=0.2),"3bet/call",IF(J12>=K12,"3bet","Call"))) -> Call | N12: 0 | O12: 1 | P12: =N12+O12 -> 1 | Q12: =IF(P12<0.2,"Fold",IF(AND(N12>=0.2,O12>=0.2),"3bet/call",IF(N12>=O12,"3bet","Call"))) -> Call
A13: A6s | B13: 0.6 | C13: 0 | D13: =B13+C13 -> 0.6 | E13: =IF(D13<0.2,"Fold",IF(AND(B13>=0.2,C13>=0.2),"3bet/call",IF(B13>=C13,"3bet","Call"))) -> 3bet | F13: 0.95 | G13: 0.05 | H13: =F13+G13 -> 1 | I13: =IF(H13<0.2,"Fold",IF(AND(F13>=0.2,G13>=0.2),"3bet/call",IF(F13>=G13,"3bet","Call"))) -> 3bet | J13: 0.25 | K13: 0.75 | L13: =J13+K13 -> 1 | M13: =IF(L13<0.2,"Fold",IF(AND(J13>=0.2,K13>=0.2),"3bet/call",IF(J13>=K13,"3bet","Call"))) -> 3bet/call | N13: 0.25 | O13: 0.75 | P13: =N13+O13 -> 1 | Q13: =IF(P13<0.2,"Fold",IF(AND(N13>=0.2,O13>=0.2),"3bet/call",IF(N13>=O13,"3bet","Call"))) -> 3bet/call
A14: A5s | B14: 0.6 | C14: 0.4 | D14: =B14+C14 -> 1 | E14: =IF(D14<0.2,"Fold",IF(AND(B14>=0.2,C14>=0.2),"3bet/call",IF(B14>=C14,"3bet","Call"))) -> 3bet/call | F14: 0.45 | G14: 0.55 | H14: =F14+G14 -> 1 | I14: =IF(H14<0.2,"Fold",IF(AND(F14>=0.2,G14>=0.2),"3bet/call",IF(F14>=G14,"3bet","Call"))) -> 3bet/call | J14: 0 | K14: 1 | L14: =J14+K14 -> 1 | M14: =IF(L14<0.2,"Fold",IF(AND(J14>=0.2,K14>=0.2),"3bet/call",IF(J14>=K14,"3bet","Call"))) -> Call | N14: 0.35 | O14: 0.65 | P14: =N14+O14 -> 1 | Q14: =IF(P14<0.2,"Fold",IF(AND(N14>=0.2,O14>=0.2),"3bet/call",IF(N14>=O14,"3bet","Call"))) -> 3bet/call
A15: A4s | B15: 0 | C15: 0.2 | D15: =B15+C15 -> 0.2 | E15: =IF(D15<0.2,"Fold",IF(AND(B15>=0.2,C15>=0.2),"3bet/call",IF(B15>=C15,"3bet","Call"))) -> Call | F15: 0.45 | G15: 0.55 | H15: =F15+G15 -> 1 | I15: =IF(H15<0.2,"Fold",IF(AND(F15>=0.2,G15>=0.2),"3bet/call",IF(F15>=G15,"3bet","Call"))) -> 3bet/call | J15: 0.25 | K15: 0.75 | L15: =J15+K15 -> 1 | M15: =IF(L15<0.2,"Fold",IF(AND(J15>=0.2,K15>=0.2),"3bet/call",IF(J15>=K15,"3bet","Call"))) -> 3bet/call | N15: 0 | O15: 1 | P15: =N15+O15 -> 1 | Q15: =IF(P15<0.2,"Fold",IF(AND(N15>=0.2,O15>=0.2),"3bet/call",IF(N15>=O15,"3bet","Call"))) -> Call
A16: A3s | B16: 0 | C16: 0 | D16: =B16+C16 -> 0 | E16: =IF(D16<0.2,"Fold",IF(AND(B16>=0.2,C16>=0.2),"3bet/call",IF(B16>=C16,"3bet","Call"))) -> Fold | F16: 0 | G16: 0.3 | H16: =F16+G16 -> 0.3 | I16: =IF(H16<0.2,"Fold",IF(AND(F16>=0.2,G16>=0.2),"3bet/call",IF(F16>=G16,"3bet","Call"))) -> Call | J16: 0.6 | K16: 0.4 | L16: =J16+K16 -> 1 | M16: =IF(L16<0.2,"Fold",IF(AND(J16>=0.2,K16>=0.2),"3bet/call",IF(J16>=K16,"3bet","Call"))) -> 3bet/call | N16: 0.25 | O16: 0.75 | P16: =N16+O16 -> 1 | Q16: =IF(P16<0.2,"Fold",IF(AND(N16>=0.2,O16>=0.2),"3bet/call",IF(N16>=O16,"3bet","Call"))) -> 3bet/call
... A173: 22 | B173: 0 | C173: 0 | D173: =B173+C173 -> 0 | E173: =IF(D173<0.2,"Fold",IF(AND(B173>=0.2,C173>=0.2),"3bet/call",IF(B173>=C173,"3bet","Call"))) -> Fold | F173: 0 | G173: 0.2 | H173: =F173+G173 -> 0.2 | I173: =IF(H173<0.2,"Fold",IF(AND(F173>=0.2,G173>=0.2),"3bet/call",IF(F173>=G173,"3bet","Call"))) -> Call | J173: 0 | K173: 1 | L173: =J173+K173 -> 1 | M173: =IF(L173<0.2,"Fold",IF(AND(J173>=0.2,K173>=0.2),"3bet/call",IF(J173>=K173,"3bet","Call"))) -> Call | N173: 0 | O173: 1 | P173: =N173+O173 -> 1 | Q173: =IF(P173<0.2,"Fold",IF(AND(N173>=0.2,O173>=0.2),"3bet/call",IF(N173>=O173,"3bet","Call"))) -> Call
A175: Ação: "Fold" se continua menos de 20%; "3bet/call" se os dois têm 20% ou mais; senão a maior. Em frequências parciais, o resto é fold.

Sheet Folds_lidos
A1: Vezes foldada por mão (lidas dos prints do painel de evolução)
A2: Folds lidos dos prints do painel (S3 e S4 de HJ, CO, BTN e SB). S1 e S2 não entram: o leitor erra em células claras. Células duvidosas foram conferidas à mão (5 corrigidas: números de 14 a 16).
A4: Mão | B4: HJ S3 | C4: HJ S4 | D4: CO S3 | E4: CO S4 | F4: BTN S3 | G4: BTN S4 | H4: SB S3 | I4: SB S4 | K4: Resumo HJ
A5: AA | B5: 0 | C5: 0 | D5: 0 | E5: 0 | F5: 0 | G5: 0 | H5: 0 | I5: 0 | L5: S3 | M5: S4
A6: AKs | B6: 0 | C6: 0 | D6: 0 | E6: 0 | F6: 0 | G6: 0 | H6: 0 | I6: 0 | K6: Total de folds | L6: =SUM(B5:B173) -> 450 | M6: =SUM(C5:C173) -> 533
A7: AQs | B7: 0 | C7: 0 | D7: 0 | E7: 0 | F7: 0 | G7: 0 | H7: 0 | I7: 0 | K7: Em mãos que o solver defende (≥80%) | L7: =SUMPRODUCT((Maos_por_spot!$D$5:$D$173>=0.8)*B5:B173) -> 7 | M7: =SUMPRODUCT((Maos_por_spot!$D$5:$D$173>=0.8)*C5:C173) -> 5
A8: AJs | B8: 0 | C8: 0 | D8: 0 | E8: 0 | F8: 0 | G8: 0 | H8: 0 | I8: 0 | K8: Em mãos que o solver defende em parte (30–80%) | L8: =SUMPRODUCT((Maos_por_spot!$D$5:$D$173>=0.3)*(Maos_por_spot!$D$5:$D$173<0.8)*B5:B173) -> 3 | M8: =SUMPRODUCT((Maos_por_spot!$D$5:$D$173>=0.3)*(Maos_por_spot!$D$5:$D$173<0.8)*C5:C173) -> 2
A9: ATs | B9: 0 | C9: 0 | D9: 0 | E9: 0 | F9: 0 | G9: 0 | H9: 0 | I9: 0 | K9: Em mãos que o solver folda (<30%) | L9: =SUMPRODUCT((Maos_por_spot!$D$5:$D$173<0.3)*B5:B173) -> 440 | M9: =SUMPRODUCT((Maos_por_spot!$D$5:$D$173<0.3)*C5:C173) -> 526
A10: A9s | B10: 0 | C10: 0 | D10: 0 | E10: 0 | F10: 0 | G10: 0 | H10: 0 | I10: 0 | K10: % dos folds em mãos defendidas (≥30%) | L10: =(L7+L8)/L6 -> 0.022222222 | M10: =(M7+M8)/M6 -> 0.013133208
A11: A8s | B11: 0 | C11: 1 | D11: 1 | E11: 0 | F11: 0 | G11: 0 | H11: 0 | I11: 0
A12: A7s | B12: 1 | C12: 0 | D12: 0 | E12: 1 | F12: 0 | G12: 0 | H12: 1 | I12: 0 | K12: Resumo CO
A13: A6s | B13: 0 | C13: 0 | D13: 0 | E13: 2 | F13: 0 | G13: 0 | H13: 0 | I13: 0 | L13: S3 | M13: S4
A14: A5s | B14: 1 | C14: 1 | D14: 0 | E14: 2 | F14: 0 | G14: 1 | H14: 0 | I14: 0 | K14: Total de folds | L14: =SUM(D5:D173) -> 619 | M14: =SUM(E5:E173) -> 644
A15: A4s | B15: 1 | C15: 1 | D15: 1 | E15: 1 | F15: 1 | G15: 0 | H15: 0 | I15: 0 | K15: Em mãos que o solver defende (≥80%) | L15: =SUMPRODUCT((Maos_por_spot!$H$5:$H$173>=0.8)*D5:D173) -> 5 | M15: =SUMPRODUCT((Maos_por_spot!$H$5:$H$173>=0.8)*E5:E173) -> 19
A16: A3s | B16: 0 | C16: 3 | D16: 4 | E16: 1 | F16: 0 | G16: 1 | H16: 0 | I16: 1 | K16: Em mãos que o solver defende em parte (30–80%) | L16: =SUMPRODUCT((Maos_por_spot!$H$5:$H$173>=0.3)*(Maos_por_spot!$H$5:$H$173<0.8)*D5:D173) -> 11 | M16: =SUMPRODUCT((Maos_por_spot!$H$5:$H$173>=0.3)*(Maos_por_spot!$H$5:$H$173<0.8)*E5:E173) -> 12
A17: A2s | B17: 2 | C17: 2 | D17: 4 | E17: 0 | F17: 1 | G17: 2 | H17: 0 | I17: 1 | K17: Em mãos que o solver folda (<30%) | L17: =SUMPRODUCT((Maos_por_spot!$H$5:$H$173<0.3)*D5:D173) -> 603 | M17: =SUMPRODUCT((Maos_por_spot!$H$5:$H$173<0.3)*E5:E173) -> 613
A18: AKo | B18: 0 | C18: 0 | D18: 0 | E18: 0 | F18: 0 | G18: 0 | H18: 0 | I18: 1 | K18: % dos folds em mãos defendidas (≥30%) | L18: =(L15+L16)/L14 -> 0.025848142 | M18: =(M15+M16)/M14 -> 0.048136646
A19: KK | B19: 0 | C19: 0 | D19: 0 | E19: 0 | F19: 0 | G19: 0 | H19: 0 | I19: 0
A20: KQs | B20: 0 | C20: 0 | D20: 0 | E20: 0 | F20: 0 | G20: 0 | H20: 0 | I20: 0 | K20: Resumo BTN
A21: KJs | B21: 0 | C21: 0 | D21: 0 | E21: 0 | F21: 0 | G21: 0 | H21: 0 | I21: 0 | L21: S3 | M21: S4
A22: KTs | B22: 0 | C22: 0 | D22: 0 | E22: 0 | F22: 0 | G22: 0 | H22: 0 | I22: 0 | K22: Total de folds | L22: =SUM(F5:F173) -> 680 | M22: =SUM(G5:G173) -> 712
A23: K9s | B23: 0 | C23: 0 | D23: 0 | E23: 1 | F23: 0 | G23: 1 | H23: 0 | I23: 1 | K23: Em mãos que o solver defende (≥80%) | L23: =SUMPRODUCT((Maos_por_spot!$L$5:$L$173>=0.8)*F5:F173) -> 37 | M23: =SUMPRODUCT((Maos_por_spot!$L$5:$L$173>=0.8)*G5:G173) -> 49
A24: K8s | B24: 0 | C24: 1 | D24: 3 | E24: 3 | F24: 2 | G24: 0 | H24: 0 | I24: 1 | K24: Em mãos que o solver defende em parte (30–80%) | L24: =SUMPRODUCT((Maos_por_spot!$L$5:$L$173>=0.3)*(Maos_por_spot!$L$5:$L$173<0.8)*F5:F173) -> 20 | M24: =SUMPRODUCT((Maos_por_spot!$L$5:$L$173>=0.3)*(Maos_por_spot!$L$5:$L$173<0.8)*G5:G173) -> 19
A25: K7s | B25: 3 | C25: 1 | D25: 2 | E25: 0 | F25: 3 | G25: 1 | H25: 1 | I25: 0 | K25: Em mãos que o solver folda (<30%) | L25: =SUMPRODUCT((Maos_por_spot!$L$5:$L$173<0.3)*F5:F173) -> 623 | M25: =SUMPRODUCT((Maos_por_spot!$L$5:$L$173<0.3)*G5:G173) -> 644
A26: K6s | B26: 2 | C26: 3 | D26: 4 | E26: 3 | F26: 2 | G26: 3 | H26: 1 | I26: 2 | K26: % dos folds em mãos defendidas (≥30%) | L26: =(L23+L24)/L22 -> 0.083823529 | M26: =(M23+M24)/M22 -> 0.095505618
A27: K5s | B27: 1 | C27: 5 | D27: 1 | E27: 2 | F27: 2 | G27: 1 | H27: 1 | I27: 4
A28: K4s | B28: 4 | C28: 2 | D28: 1 | E28: 2 | F28: 3 | G28: 0 | H28: 4 | I28: 1 | K28: Resumo SB
A29: K3s | B29: 4 | C29: 1 | D29: 1 | E29: 3 | F29: 4 | G29: 3 | H29: 2 | I29: 1 | L29: S3 | M29: S4
A30: K2s | B30: 0 | C30: 0 | D30: 3 | E30: 1 | F30: 3 | G30: 2 | H30: 5 | I30: 3 | K30: Total de folds | L30: =SUM(H5:H173) -> 630 | M30: =SUM(I5:I173) -> 726
A31: AQo | B31: 0 | C31: 0 | D31: 0 | E31: 0 | F31: 0 | G31: 0 | H31: 0 | I31: 0 | K31: Em mãos que o solver defende (≥80%) | L31: =SUMPRODUCT((Maos_por_spot!$P$5:$P$173>=0.8)*H5:H173) -> 44 | M31: =SUMPRODUCT((Maos_por_spot!$P$5:$P$173>=0.8)*I5:I173) -> 69
A32: KQo | B32: 2 | C32: 1 | D32: 0 | E32: 2 | F32: 0 | G32: 0 | H32: 0 | I32: 1 | K32: Em mãos que o solver defende em parte (30–80%) | L32: =SUMPRODUCT((Maos_por_spot!$P$5:$P$173>=0.3)*(Maos_por_spot!$P$5:$P$173<0.8)*H5:H173) -> 12 | M32: =SUMPRODUCT((Maos_por_spot!$P$5:$P$173>=0.3)*(Maos_por_spot!$P$5:$P$173<0.8)*I5:I173) -> 13
A33: QQ | B33: 0 | C33: 0 | D33: 0 | E33: 0 | F33: 0 | G33: 0 | H33: 0 | I33: 0 | K33: Em mãos que o solver folda (<30%) | L33: =SUMPRODUCT((Maos_por_spot!$P$5:$P$173<0.3)*H5:H173) -> 574 | M33: =SUMPRODUCT((Maos_por_spot!$P$5:$P$173<0.3)*I5:I173) -> 644
A34: QJs | B34: 1 | C34: 1 | D34: 1 | E34: 0 | F34: 0 | G34: 0 | H34: 0 | I34: 0 | K34: % dos folds em mãos defendidas (≥30%) | L34: =(L31+L32)/L30 -> 0.088888889 | M34: =(M31+M32)/M30 -> 0.11294766
A35: QTs | B35: 0 | C35: 0 | D35: 0 | E35: 1 | F35: 0 | G35: 1 | H35: 0 | I35: 1
A36: Q9s | B36: 0 | C36: 2 | D36: 0 | E36: 0 | F36: 1 | G36: 0 | H36: 0 | I36: 0
A37: Q8s | B37: 2 | C37: 0 | D37: 2 | E37: 2 | F37: 3 | G37: 4 | H37: 1 | I37: 1
A38: Q7s | B38: 5 | C38: 2 | D38: 0 | E38: 2 | F38: 1 | G38: 5 | H38: 1 | I38: 5
A39: Q6s | B39: 2 | C39: 1 | D39: 4 | E39: 2 | F39: 0 | G39: 1 | H39: 2 | I39: 1
A40: Q5s | B40: 5 | C40: 2 | D40: 1 | E40: 1 | F40: 1 | G40: 1 | H40: 1 | I40: 3
A41: Q4s | B41: 2 | C41: 0 | D41: 2 | E41: 2 | F41: 2 | G41: 6 | H41: 5 | I41: 5
...

Sheet Folds_total
A1: Vezes foldada por mão: total de todas as semanas (prints do Hand2Note, aba Fold)
A2: Contagens lidas dos prints [LUC] CALL-OPEN HJ, CO, BTN e SB (matriz Fold). Células claras de duas casas foram conferidas à mão. Valor em azul = lido do print.
A4: Mão | B4: HJ | C4: CO | D4: BTN | E4: SB | G4: Resumo por posição
A5: AA | B5: 0 | C5: 0 | D5: 0 | E5: 0 | H5: HJ | I5: CO | J5: BTN | K5: SB
A6: AKs | B6: 0 | C6: 0 | D6: 0 | E6: 0 | G6: Total de folds | H6: =SUM(B5:B173) -> 1740 | I6: =SUM(C5:C173) -> 2158 | J6: =SUM(D5:D173) -> 2313 | K6: =SUM(E5:E173) -> 2265
A7: AQs | B7: 0 | C7: 0 | D7: 0 | E7: 0 | G7: Em mãos que o solver defende (≥80%) | H7: =SUMPRODUCT((Maos_por_spot!$D$5:$D$173>=0.8)*B5:B173) -> 22 | I7: =SUMPRODUCT((Maos_por_spot!$H$5:$H$173>=0.8)*C5:C173) -> 27 | J7: =SUMPRODUCT((Maos_por_spot!$L$5:$L$173>=0.8)*D5:D173) -> 126 | K7: =SUMPRODUCT((Maos_por_spot!$P$5:$P$173>=0.8)*E5:E173) -> 169
A8: AJs | B8: 0 | C8: 0 | D8: 0 | E8: 0 | G8: Em mãos que o solver defende em parte (30–80%) | H8: =SUMPRODUCT((Maos_por_spot!$D$5:$D$173>=0.3)*(Maos_por_spot!$D$5:$D$173<0.8)*B5:B173) -> 6 | I8: =SUMPRODUCT((Maos_por_spot!$H$5:$H$173>=0.3)*(Maos_por_spot!$H$5:$H$173<0.8)*C5:C173) -> 35 | J8: =SUMPRODUCT((Maos_por_spot!$L$5:$L$173>=0.3)*(Maos_por_spot!$L$5:$L$173<0.8)*D5:D173) -> 51 | K8: =SUMPRODUCT((Maos_por_spot!$P$5:$P$173>=0.3)*(Maos_por_spot!$P$5:$P$173<0.8)*E5:E173) -> 35
A9: ATs | B9: 0 | C9: 0 | D9: 0 | E9: 0 | G9: Em mãos que o solver folda (<30%) | H9: =SUMPRODUCT((Maos_por_spot!$D$5:$D$173<0.3)*B5:B173) -> 1712 | I9: =SUMPRODUCT((Maos_por_spot!$H$5:$H$173<0.3)*C5:C173) -> 2096 | J9: =SUMPRODUCT((Maos_por_spot!$L$5:$L$173<0.3)*D5:D173) -> 2136 | K9: =SUMPRODUCT((Maos_por_spot!$P$5:$P$173<0.3)*E5:E173) -> 2061
A10: A9s | B10: 0 | C10: 0 | D10: 1 | E10: 0 | G10: % dos folds em mãos defendidas (≥80%) | H10: =H7/H6 -> 0.012643678 | I10: =I7/I6 -> 0.012511585 | J10: =J7/J6 -> 0.054474708 | K10: =K7/K6 -> 0.074613687
A11: A8s | B11: 2 | C11: 1 | D11: 0 | E11: 0
A12: A7s | B12: 1 | C12: 0 | D12: 0 | E12: 1 | G12: Stat acumulado do HUD (Call open) e lucro da ação
A13: A6s | B13: 0 | C13: 2 | D13: 0 | E13: 0 | H13: HJ | I13: CO | J13: BTN | K13: SB
A14: A5s | B14: 3 | C14: 2 | D14: 1 | E14: 0 | G14: Stat Value (%) | H14: 0.07 | I14: 0.095 | J14: 0.1 | K14: 0.12
A15: A4s | B15: 3 | C15: 3 | D15: 1 | E15: 0 | G15: Base solver (call, 40bb) | H15: =Resumo!D5 -> 0.055 | I15: =Resumo!D6 -> 0.08 | J15: =Resumo!D7 -> 0.151 | K15: =Resumo!D8 -> 0.116
A16: A3s | B16: 8 | C16: 8 | D16: 1 | E16: 0 | G16: Diferença (stat − base) | H16: =H14-H15 -> 0.015 | I16: =I14-I15 -> 0.015 | J16: =J14-J15 -> -0.051 | K16: =K14-K15 -> 0.004
A17: A2s | B17: 5 | C17: 4 | D17: 4 | E17: 1 | G17: Action Profit (bb/mão) | H17: -2.1 | I17: 1.1 | J17: 2.4 | K17: 0.77
A18: AKo | B18: 0 | C18: 0 | D18: 0 | E18: 1
A19: KK | B19: 0 | C19: 0 | D19: 0 | E19: 0 | G19: Os números do Stat Value e do Action Profit vêm do cabeçalho de cada print do HUD, informados pelo usuário.
A20: KQs | B20: 0 | C20: 0 | D20: 0 | E20: 0
A21: KJs | B21: 0 | C21: 0 | D21: 0 | E21: 0
A22: KTs | B22: 0 | C22: 0 | D22: 0 | E22: 0
A23: K9s | B23: 0 | C23: 1 | D23: 1 | E23: 1
A24: K8s | B24: 2 | C24: 8 | D24: 2 | E24: 1
A25: K7s | B25: 5 | C25: 2 | D25: 4 | E25: 0
A26: K6s | B26: 5 | C26: 7 | D26: 8 | E26: 4
A27: K5s | B27: 11 | C27: 7 | D27: 8 | E27: 9
A28: K4s | B28: 9 | C28: 4 | D28: 7 | E28: 3
A29: K3s | B29: 7 | C29: 9 | D29: 15 | E29: 6
A30: K2s | B30: 4 | C30: 5 | D30: 9 | E30: 10
A31: AQo | B31: 1 | C31: 0 | D31: 0 | E31: 0
... A173: 22 | B173: 7 | C173: 7 | D173: 5 | E173: 8

Sheet Erros_comuns
A1: Erros mais comuns: mãos que o solver defende (40bb) e você folda com frequência
A2: Lista só as mãos com 7 ou mais folds (poucos folds são desconsiderados: costumam ser spot específico). "Defende só em parte" = o fold pode estar certo na maior parte das vezes.
A4: Posição | B4: Mão | C4: Família | D4: Folds (total) | E4: Solver continua | F4: Ação do solver | G4: Peso (folds × continua) | H4: Leitura
A5: CO | B5: K8s | C5: =IF(RIGHT(B5,1)="o","Offsuit",IF(RIGHT(B5,1)="s","Suited","Par")) -> Suited | D5: =INDEX(Folds_total!$C$5:$C$173,MATCH($B5,Folds_total!$A$5:$A$173,0)) -> 8 | E5: =INDEX(Maos_por_spot!$H$5:$H$173,MATCH($B5,Maos_por_spot!$A$5:$A$173,0)) -> 0.55 | F5: =INDEX(Maos_por_spot!$I$5:$I$173,MATCH($B5,Maos_por_spot!$A$5:$A$173,0)) -> 3bet | G5: =D5*E5 -> 4.4 | H5: =IF(E5>=0.8,"Erro claro: o solver quase sempre defende","Defende só em parte: pode estar certo") -> Defende só em parte: pode estar certo
A6: CO | B6: KJo | C6: =IF(RIGHT(B6,1)="o","Offsuit",IF(RIGHT(B6,1)="s","Suited","Par")) -> Offsuit | D6: =INDEX(Folds_total!$C$5:$C$173,MATCH($B6,Folds_total!$A$5:$A$173,0)) -> 7 | E6: =INDEX(Maos_por_spot!$H$5:$H$173,MATCH($B6,Maos_por_spot!$A$5:$A$173,0)) -> 0.5 | F6: =INDEX(Maos_por_spot!$I$5:$I$173,MATCH($B6,Maos_por_spot!$A$5:$A$173,0)) -> 3bet/call | G6: =D6*E6 -> 3.5 | H6: =IF(E6>=0.8,"Erro claro: o solver quase sempre defende","Defende só em parte: pode estar certo") -> Defende só em parte: pode estar certo
A7: CO | B7: 44 | C7: =IF(RIGHT(B7,1)="o","Offsuit",IF(RIGHT(B7,1)="s","Suited","Par")) -> Par | D7: =INDEX(Folds_total!$C$5:$C$173,MATCH($B7,Folds_total!$A$5:$A$173,0)) -> 7 | E7: =INDEX(Maos_por_spot!$H$5:$H$173,MATCH($B7,Maos_por_spot!$A$5:$A$173,0)) -> 0.4 | F7: =INDEX(Maos_por_spot!$I$5:$I$173,MATCH($B7,Maos_por_spot!$A$5:$A$173,0)) -> Call | G7: =D7*E7 -> 2.8 | H7: =IF(E7>=0.8,"Erro claro: o solver quase sempre defende","Defende só em parte: pode estar certo") -> Defende só em parte: pode estar certo
A8: BTN | B8: A9o | C8: =IF(RIGHT(B8,1)="o","Offsuit",IF(RIGHT(B8,1)="s","Suited","Par")) -> Offsuit | D8: =INDEX(Folds_total!$D$5:$D$173,MATCH($B8,Folds_total!$A$5:$A$173,0)) -> 17 | E8: =INDEX(Maos_por_spot!$L$5:$L$173,MATCH($B8,Maos_por_spot!$A$5:$A$173,0)) -> 1 | F8: =INDEX(Maos_por_spot!$M$5:$M$173,MATCH($B8,Maos_por_spot!$A$5:$A$173,0)) -> 3bet/call | G8: =D8*E8 -> 17 | H8: =IF(E8>=0.8,"Erro claro: o solver quase sempre defende","Defende só em parte: pode estar certo") -> Erro claro: o solver quase sempre defende
A9: BTN | B9: QJo | C9: =IF(RIGHT(B9,1)="o","Offsuit",IF(RIGHT(B9,1)="s","Suited","Par")) -> Offsuit | D9: =INDEX(Folds_total!$D$5:$D$173,MATCH($B9,Folds_total!$A$5:$A$173,0)) -> 13 | E9: =INDEX(Maos_por_spot!$L$5:$L$173,MATCH($B9,Maos_por_spot!$A$5:$A$173,0)) -> 1 | F9: =INDEX(Maos_por_spot!$M$5:$M$173,MATCH($B9,Maos_por_spot!$A$5:$A$173,0)) -> 3bet/call | G9: =D9*E9 -> 13 | H9: =IF(E9>=0.8,"Erro claro: o solver quase sempre defende","Defende só em parte: pode estar certo") -> Erro claro: o solver quase sempre defende
A10: BTN | B10: A8o | C10: =IF(RIGHT(B10,1)="o","Offsuit",IF(RIGHT(B10,1)="s","Suited","Par")) -> Offsuit | D10: =INDEX(Folds_total!$D$5:$D$173,MATCH($B10,Folds_total!$A$5:$A$173,0)) -> 33 | E10: =INDEX(Maos_por_spot!$L$5:$L$173,MATCH($B10,Maos_por_spot!$A$5:$A$173,0)) -> 0.4 | F10: =INDEX(Maos_por_spot!$M$5:$M$173,MATCH($B10,Maos_por_spot!$A$5:$A$173,0)) -> 3bet | G10: =D10*E10 -> 13.2 | H10: =IF(E10>=0.8,"Erro claro: o solver quase sempre defende","Defende só em parte: pode estar certo") -> Defende só em parte: pode estar certo
A11: BTN | B11: KTo | C11: =IF(RIGHT(B11,1)="o","Offsuit",IF(RIGHT(B11,1)="s","Suited","Par")) -> Offsuit | D11: =INDEX(Folds_total!$D$5:$D$173,MATCH($B11,Folds_total!$A$5:$A$173,0)) -> 11 | E11: =INDEX(Maos_por_spot!$L$5:$L$173,MATCH($B11,Maos_por_spot!$A$5:$A$173,0)) -> 1 | F11: =INDEX(Maos_por_spot!$M$5:$M$173,MATCH($B11,Maos_por_spot!$A$5:$A$173,0)) -> 3bet/call | G11: =D11*E11 -> 11 | H11: =IF(E11>=0.8,"Erro claro: o solver quase sempre defende","Defende só em parte: pode estar certo") -> Erro claro: o solver quase sempre defende
A12: BTN | B12: Q8s | C12: =IF(RIGHT(B12,1)="o","Offsuit",IF(RIGHT(B12,1)="s","Suited","Par")) -> Suited | D12: =INDEX(Folds_total!$D$5:$D$173,MATCH($B12,Folds_total!$A$5:$A$173,0)) -> 9 | E12: =INDEX(Maos_por_spot!$L$5:$L$173,MATCH($B12,Maos_por_spot!$A$5:$A$173,0)) -> 1 | F12: =INDEX(Maos_por_spot!$M$5:$M$173,MATCH($B12,Maos_por_spot!$A$5:$A$173,0)) -> 3bet | G12: =D12*E12 -> 9 | H12: =IF(E12>=0.8,"Erro claro: o solver quase sempre defende","Defende só em parte: pode estar certo") -> Erro claro: o solver quase sempre defende
A13: BTN | B13: T8s | C13: =IF(RIGHT(B13,1)="o","Offsuit",IF(RIGHT(B13,1)="s","Suited","Par")) -> Suited | D13: =INDEX(Folds_total!$D$5:$D$173,MATCH($B13,Folds_total!$A$5:$A$173,0)) -> 7 | E13: =INDEX(Maos_por_spot!$L$5:$L$173,MATCH($B13,Maos_por_spot!$A$5:$A$173,0)) -> 1 | F13: =INDEX(Maos_por_spot!$M$5:$M$173,MATCH($B13,Maos_por_spot!$A$5:$A$173,0)) -> 3bet/call | G13: =D13*E13 -> 7 | H13: =IF(E13>=0.8,"Erro claro: o solver quase sempre defende","Defende só em parte: pode estar certo") -> Erro claro: o solver quase sempre defende
A14: BTN | B14: 87s | C14: =IF(RIGHT(B14,1)="o","Offsuit",IF(RIGHT(B14,1)="s","Suited","Par")) -> Suited | D14: =INDEX(Folds_total!$D$5:$D$173,MATCH($B14,Folds_total!$A$5:$A$173,0)) -> 7 | E14: =INDEX(Maos_por_spot!$L$5:$L$173,MATCH($B14,Maos_por_spot!$A$5:$A$173,0)) -> 1 | F14: =INDEX(Maos_por_spot!$M$5:$M$173,MATCH($B14,Maos_por_spot!$A$5:$A$173,0)) -> 3bet/call | G14: =D14*E14 -> 7 | H14: =IF(E14>=0.8,"Erro claro: o solver quase sempre defende","Defende só em parte: pode estar certo") -> Erro claro: o solver quase sempre defende
A15: BTN | B15: 33 | C15: =IF(RIGHT(B15,1)="o","Offsuit",IF(RIGHT(B15,1)="s","Suited","Par")) -> Par | D15: =INDEX(Folds_total!$D$5:$D$173,MATCH($B15,Folds_total!$A$5:$A$173,0)) -> 7 | E15: =INDEX(Maos_por_spot!$L$5:$L$173,MATCH($B15,Maos_por_spot!$A$5:$A$173,0)) -> 1 | F15: =INDEX(Maos_por_spot!$M$5:$M$173,MATCH($B15,Maos_por_spot!$A$5:$A$173,0)) -> Call | G15: =D15*E15 -> 7 | H15: =IF(E15>=0.8,"Erro claro: o solver quase sempre defende","Defende só em parte: pode estar certo") -> Erro claro: o solver quase sempre defende
A16: BTN | B16: K6s | C16: =IF(RIGHT(B16,1)="o","Offsuit",IF(RIGHT(B16,1)="s","Suited","Par")) -> Suited | D16: =INDEX(Folds_total!$D$5:$D$173,MATCH($B16,Folds_total!$A$5:$A$173,0)) -> 8 | E16: =INDEX(Maos_por_spot!$L$5:$L$173,MATCH($B16,Maos_por_spot!$A$5:$A$173,0)) -> 0.8 | F16: =INDEX(Maos_por_spot!$M$5:$M$173,MATCH($B16,Maos_por_spot!$A$5:$A$173,0)) -> 3bet/call | G16: =D16*E16 -> 6.4 | H16: =IF(E16>=0.8,"Erro claro: o solver quase sempre defende","Defende só em parte: pode estar certo") -> Erro claro: o solver quase sempre defende
A17: BTN | B17: K5s | C17: =IF(RIGHT(B17,1)="o","Offsuit",IF(RIGHT(B17,1)="s","Suited","Par")) -> Suited | D17: =INDEX(Folds_total!$D$5:$D$173,MATCH($B17,Folds_total!$A$5:$A$173,0)) -> 8 | E17: =INDEX(Maos_por_spot!$L$5:$L$173,MATCH($B17,Maos_por_spot!$A$5:$A$173,0)) -> 0.4 | F17: =INDEX(Maos_por_spot!$M$5:$M$173,MATCH($B17,Maos_por_spot!$A$5:$A$173,0)) -> 3bet | G17: =D17*E17 -> 3.2 | H17: =IF(E17>=0.8,"Erro claro: o solver quase sempre defende","Defende só em parte: pode estar certo") -> Defende só em parte: pode estar certo
A18: SB | B18: KTo | C18: =IF(RIGHT(B18,1)="o","Offsuit",IF(RIGHT(B18,1)="s","Suited","Par")) -> Offsuit | D18: =INDEX(Folds_total!$E$5:$E$173,MATCH($B18,Folds_total!$A$5:$A$173,0)) -> 19 | E18: =INDEX(Maos_por_spot!$P$5:$P$173,MATCH($B18,Maos_por_spot!$A$5:$A$173,0)) -> 1 | F18: =INDEX(Maos_por_spot!$Q$5:$Q$173,MATCH($B18,Maos_por_spot!$A$5:$A$173,0)) -> 3bet/call | G18: =D18*E18 -> 19 | H18: =IF(E18>=0.8,"Erro claro: o solver quase sempre defende","Defende só em parte: pode estar certo") -> Erro claro: o solver quase sempre defende
A19: SB | B19: JTo | C19: =IF(RIGHT(B19,1)="o","Offsuit",IF(RIGHT(B19,1)="s","Suited","Par")) -> Offsuit | D19: =INDEX(Folds_total!$E$5:$E$173,MATCH($B19,Folds_total!$A$5:$A$173,0)) -> 15 | E19: =INDEX(Maos_por_spot!$P$5:$P$173,MATCH($B19,Maos_por_spot!$A$5:$A$173,0)) -> 1 | F19: =INDEX(Maos_por_spot!$Q$5:$Q$173,MATCH($B19,Maos_por_spot!$A$5:$A$173,0)) -> 3bet/call | G19: =D19*E19 -> 15 | H19: =IF(E19>=0.8,"Erro claro: o solver quase sempre defende","Defende só em parte: pode estar certo") -> Erro claro: o solver quase sempre defende
A20: SB | B20: A8o | C20: =IF(RIGHT(B20,1)="o","Offsuit",IF(RIGHT(B20,1)="s","Suited","Par")) -> Offsuit | D20: =INDEX(Folds_total!$E$5:$E$173,MATCH($B20,Folds_total!$A$5:$A$173,0)) -> 14 | E20: =INDEX(Maos_por_spot!$P$5:$P$173,MATCH($B20,Maos_por_spot!$A$5:$A$173,0)) -> 1 | F20: =INDEX(Maos_por_spot!$Q$5:$Q$173,MATCH($B20,Maos_por_spot!$A$5:$A$173,0)) -> 3bet/call | G20: =D20*E20 -> 14 | H20: =IF(E20>=0.8,"Erro claro: o solver quase sempre defende","Defende só em parte: pode estar certo") -> Erro claro: o solver quase sempre defende
A21: SB | B21: A7o | C21: =IF(RIGHT(B21,1)="o","Offsuit",IF(RIGHT(B21,1)="s","Suited","Par")) -> Offsuit | D21: =INDEX(Folds_total!$E$5:$E$173,MATCH($B21,Folds_total!$A$5:$A$173,0)) -> 21 | E21: =INDEX(Maos_por_spot!$P$5:$P$173,MATCH($B21,Maos_por_spot!$A$5:$A$173,0)) -> 0.6 | F21: =INDEX(Maos_por_spot!$Q$5:$Q$173,MATCH($B21,Maos_por_spot!$A$5:$A$173,0)) -> 3bet | G21: =D21*E21 -> 12.6 | H21: =IF(E21>=0.8,"Erro claro: o solver quase sempre defende","Defende só em parte: pode estar certo") -> Defende só em parte: pode estar certo
A22: SB | B22: QTo | C22: =IF(RIGHT(B22,1)="o","Offsuit",IF(RIGHT(B22,1)="s","Suited","Par")) -> Offsuit | D22: =INDEX(Folds_total!$E$5:$E$173,MATCH($B22,Folds_total!$A$5:$A$173,0)) -> 12 | E22: =INDEX(Maos_por_spot!$P$5:$P$173,MATCH($B22,Maos_por_spot!$A$5:$A$173,0)) -> 1 | F22: =INDEX(Maos_por_spot!$Q$5:$Q$173,MATCH($B22,Maos_por_spot!$A$5:$A$173,0)) -> 3bet/call | G22: =D22*E22 -> 12 | H22: =IF(E22>=0.8,"Erro claro: o solver quase sempre defende","Defende só em parte: pode estar certo") -> Erro claro: o solver quase sempre defende
A23: SB | B23: A9o | C23: =IF(RIGHT(B23,1)="o","Offsuit",IF(RIGHT(B23,1)="s","Suited","Par")) -> Offsuit | D23: =INDEX(Folds_total!$E$5:$E$173,MATCH($B23,Folds_total!$A$5:$A$173,0)) -> 12 | E23: =INDEX(Maos_por_spot!$P$5:$P$173,MATCH($B23,Maos_por_spot!$A$5:$A$173,0)) -> 1 | F23: =INDEX(Maos_por_spot!$Q$5:$Q$173,MATCH($B23,Maos_por_spot!$A$5:$A$173,0)) -> 3bet | G23: =D23*E23 -> 12 | H23: =IF(E23>=0.8,"Erro claro: o solver quase sempre defende","Defende só em parte: pode estar certo") -> Erro claro: o solver quase sempre defende
A24: SB | B24: Q7s | C24: =IF(RIGHT(B24,1)="o","Offsuit",IF(RIGHT(B24,1)="s","Suited","Par")) -> Suited | D24: =INDEX(Folds_total!$E$5:$E$173,MATCH($B24,Folds_total!$A$5:$A$173,0)) -> 10 | E24: =INDEX(Maos_por_spot!$P$5:$P$173,MATCH($B24,Maos_por_spot!$A$5:$A$173,0)) -> 1 | F24: =INDEX(Maos_por_spot!$Q$5:$Q$173,MATCH($B24,Maos_por_spot!$A$5:$A$173,0)) -> 3bet/call | G24: =D24*E24 -> 10 | H24: =IF(E24>=0.8,"Erro claro: o solver quase sempre defende","Defende só em parte: pode estar certo") -> Erro claro: o solver quase sempre defende
A25: SB | B25: K5s | C25: =IF(RIGHT(B25,1)="o","Offsuit",IF(RIGHT(B25,1)="s","Suited","Par")) -> Suited | D25: =INDEX(Folds_total!$E$5:$E$173,MATCH($B25,Folds_total!$A$5:$A$173,0)) -> 9 | E25: =INDEX(Maos_por_spot!$P$5:$P$173,MATCH($B25,Maos_por_spot!$A$5:$A$173,0)) -> 1 | F25: =INDEX(Maos_por_spot!$Q$5:$Q$173,MATCH($B25,Maos_por_spot!$A$5:$A$173,0)) -> 3bet/call | G25: =D25*E25 -> 9 | H25: =IF(E25>=0.8,"Erro claro: o solver quase sempre defende","Defende só em parte: pode estar certo") -> Erro claro: o solver quase sempre defende
A26: SB | B26: 22 | C26: =IF(RIGHT(B26,1)="o","Offsuit",IF(RIGHT(B26,1)="s","Suited","Par")) -> Par | D26: =INDEX(Folds_total!$E$5:$E$173,MATCH($B26,Folds_total!$A$5:$A$173,0)) -> 8 | E26: =INDEX(Maos_por_spot!$P$5:$P$173,MATCH($B26,Maos_por_spot!$A$5:$A$173,0)) -> 1 | F26: =INDEX(Maos_por_spot!$Q$5:$Q$173,MATCH($B26,Maos_por_spot!$A$5:$A$173,0)) -> Call | G26: =D26*E26 -> 8 | H26: =IF(E26>=0.8,"Erro claro: o solver quase sempre defende","Defende só em parte: pode estar certo") -> Erro claro: o solver quase sempre defende
A27: SB | B27: QJo | C27: =IF(RIGHT(B27,1)="o","Offsuit",IF(RIGHT(B27,1)="s","Suited","Par")) -> Offsuit | D27: =INDEX(Folds_total!$E$5:$E$173,MATCH($B27,Folds_total!$A$5:$A$173,0)) -> 7 | E27: =INDEX(Maos_por_spot!$P$5:$P$173,MATCH($B27,Maos_por_spot!$A$5:$A$173,0)) -> 1 | F27: =INDEX(Maos_por_spot!$Q$5:$Q$173,MATCH($B27,Maos_por_spot!$A$5:$A$173,0)) -> 3bet/call | G27: =D27*E27 -> 7 | H27: =IF(E27>=0.8,"Erro claro: o solver quase sempre defende","Defende só em parte: pode estar certo") -> Erro claro: o solver quase sempre defende
A28: SB | B28: 54s | C28: =IF(RIGHT(B28,1)="o","Offsuit",IF(RIGHT(B28,1)="s","Suited","Par")) -> Suited | D28: =INDEX(Folds_total!$E$5:$E$173,MATCH($B28,Folds_total!$A$5:$A$173,0)) -> 10 | E28: =INDEX(Maos_por_spot!$P$5:$P$173,MATCH($B28,Maos_por_spot!$A$5:$A$173,0)) -> 0.45 | F28: =INDEX(Maos_por_spot!$Q$5:$Q$173,MATCH($B28,Maos_por_spot!$A$5:$A$173,0)) -> Call | G28: =D28*E28 -> 4.5 | H28: =IF(E28>=0.8,"Erro claro: o solver quase sempre defende","Defende só em parte: pode estar certo") -> Defende só em parte: pode estar certo
A30: Folds por família (só mãos da lista acima)
A31: Posição | B31: Offsuit | C31: Suited | D31: Par | E31: Total na lista
A32: CO | B32: =SUMIFS($D$5:$D$28,$A$5:$A$28,$A32,$C$5:$C$28,"Offsuit") -> 7 | C32: =SUMIFS($D$5:$D$28,$A$5:$A$28,$A32,$C$5:$C$28,"Suited") -> 8 | D32: =SUMIFS($D$5:$D$28,$A$5:$A$28,$A32,$C$5:$C$28,"Par") -> 7 | E32: =SUM(B32:D32) -> 22
A33: BTN | B33: =SUMIFS($D$5:$D$28,$A$5:$A$28,$A33,$C$5:$C$28,"Offsuit") -> 74 | C33: =SUMIFS($D$5:$D$28,$A$5:$A$28,$A33,$C$5:$C$28,"Suited") -> 39 | D33: =SUMIFS($D$5:$D$28,$A$5:$A$28,$A33,$C$5:$C$28,"Par") -> 7 | E33: =SUM(B33:D33) -> 120
A34: SB | B34: =SUMIFS($D$5:$D$28,$A$5:$A$28,$A34,$C$5:$C$28,"Offsuit") -> 100 | C34: =SUMIFS($D$5:$D$28,$A$5:$A$28,$A34,$C$5:$C$28,"Suited") -> 29 | D34: =SUMIFS($D$5:$D$28,$A$5:$A$28,$A34,$C$5:$C$28,"Par") -> 8 | E34: =SUM(B34:D34) -> 137
A36: HJ não aparece: nenhuma mão defendida pelo solver passa de 6 folds (KQo 6, ATo 4). Não há erro sistemático no HJ.
A37: No CO, as mãos da lista são defendidas só em parte pelo solver (K8s, KJo e 44, entre 40% e 55%). Também não há erro claro.
A38: BTN e SB concentram os erros: offsuit (A9o, A8o, QJo, KTo, QTo, JTo) e suited fracos (Q8s, Q7s, K6s, K5s, T8s, 87s), além de 33 e 22.
A39: Ações do solver nessas mãos: as offsuit são "3bet/call" (mistas), então o fold perde o 3bet e o call. Os suited fracos e os pares pequenos são call.
A40: A8o no BTN (38%) e A7o no SB (58%) têm contagens altas porque o solver defende só em parte: boa parte dos folds é correta.

Sheet Mais_foldadas
A1: Mãos defendidas pelo solver que você mais folda (S3 + S4)
A2: Folds vêm da aba Folds_lidos; 3bet e call do solver vêm da aba Maos_por_spot (base: hero contra o open da posição à direita, 40bb). Só entram mãos com 3 ou mais folds nas duas semanas e continua de 30% ou mais.
A4: Posição | B4: Mão | C4: Folds S3 | D4: Folds S4 | E4: Total | F4: Solver 3bet | G4: Solver call | H4: Solver continua | I4: Ação dominante do solver
A5: CO | B5: K8s | C5: =INDEX(Folds_lidos!$D$5:$D$173,MATCH($B5,Folds_lidos!$A$5:$A$173,0)) -> 3 | D5: =INDEX(Folds_lidos!$E$5:$E$173,MATCH($B5,Folds_lidos!$A$5:$A$173,0)) -> 3 | E5: =C5+D5 -> 6 | F5: =INDEX(Maos_por_spot!$F$5:$F$173,MATCH($B5,Maos_por_spot!$A$5:$A$173,0)) -> 0.55 | G5: =INDEX(Maos_por_spot!$G$5:$G$173,MATCH($B5,Maos_por_spot!$A$5:$A$173,0)) -> 0 | H5: =INDEX(Maos_por_spot!$H$5:$H$173,MATCH($B5,Maos_por_spot!$A$5:$A$173,0)) -> 0.55 | I5: =IF(H5<0.2,"Fold",IF(AND(F5>=0.2,G5>=0.2),"3bet/call",IF(F5>=G5,"3bet","Call"))) -> 3bet
A6: CO | B6: KJo | C6: =INDEX(Folds_lidos!$D$5:$D$173,MATCH($B6,Folds_lidos!$A$5:$A$173,0)) -> 2 | D6: =INDEX(Folds_lidos!$E$5:$E$173,MATCH($B6,Folds_lidos!$A$5:$A$173,0)) -> 3 | E6: =C6+D6 -> 5 | F6: =INDEX(Maos_por_spot!$F$5:$F$173,MATCH($B6,Maos_por_spot!$A$5:$A$173,0)) -> 0.3 | G6: =INDEX(Maos_por_spot!$G$5:$G$173,MATCH($B6,Maos_por_spot!$A$5:$A$173,0)) -> 0.2 | H6: =INDEX(Maos_por_spot!$H$5:$H$173,MATCH($B6,Maos_por_spot!$A$5:$A$173,0)) -> 0.5 | I6: =IF(H6<0.2,"Fold",IF(AND(F6>=0.2,G6>=0.2),"3bet/call",IF(F6>=G6,"3bet","Call"))) -> 3bet/call
A7: CO | B7: 44 | C7: =INDEX(Folds_lidos!$D$5:$D$173,MATCH($B7,Folds_lidos!$A$5:$A$173,0)) -> 2 | D7: =INDEX(Folds_lidos!$E$5:$E$173,MATCH($B7,Folds_lidos!$A$5:$A$173,0)) -> 2 | E7: =C7+D7 -> 4 | F7: =INDEX(Maos_por_spot!$F$5:$F$173,MATCH($B7,Maos_por_spot!$A$5:$A$173,0)) -> 0 | G7: =INDEX(Maos_por_spot!$G$5:$G$173,MATCH($B7,Maos_por_spot!$A$5:$A$173,0)) -> 0.4 | H7: =INDEX(Maos_por_spot!$H$5:$H$173,MATCH($B7,Maos_por_spot!$A$5:$A$173,0)) -> 0.4 | I7: =IF(H7<0.2,"Fold",IF(AND(F7>=0.2,G7>=0.2),"3bet/call",IF(F7>=G7,"3bet","Call"))) -> Call
A8: CO | B8: JTs | C8: =INDEX(Folds_lidos!$D$5:$D$173,MATCH($B8,Folds_lidos!$A$5:$A$173,0)) -> 0 | D8: =INDEX(Folds_lidos!$E$5:$E$173,MATCH($B8,Folds_lidos!$A$5:$A$173,0)) -> 3 | E8: =C8+D8 -> 3 | F8: =INDEX(Maos_por_spot!$F$5:$F$173,MATCH($B8,Maos_por_spot!$A$5:$A$173,0)) -> 0.3 | G8: =INDEX(Maos_por_spot!$G$5:$G$173,MATCH($B8,Maos_por_spot!$A$5:$A$173,0)) -> 0.7 | H8: =INDEX(Maos_por_spot!$H$5:$H$173,MATCH($B8,Maos_por_spot!$A$5:$A$173,0)) -> 1 | I8: =IF(H8<0.2,"Fold",IF(AND(F8>=0.2,G8>=0.2),"3bet/call",IF(F8>=G8,"3bet","Call"))) -> 3bet/call
A9: CO | B9: J9s | C9: =INDEX(Folds_lidos!$D$5:$D$173,MATCH($B9,Folds_lidos!$A$5:$A$173,0)) -> 2 | D9: =INDEX(Folds_lidos!$E$5:$E$173,MATCH($B9,Folds_lidos!$A$5:$A$173,0)) -> 1 | E9: =C9+D9 -> 3 | F9: =INDEX(Maos_por_spot!$F$5:$F$173,MATCH($B9,Maos_por_spot!$A$5:$A$173,0)) -> 0.7 | G9: =INDEX(Maos_por_spot!$G$5:$G$173,MATCH($B9,Maos_por_spot!$A$5:$A$173,0)) -> 0.3 | H9: =INDEX(Maos_por_spot!$H$5:$H$173,MATCH($B9,Maos_por_spot!$A$5:$A$173,0)) -> 1 | I9: =IF(H9<0.2,"Fold",IF(AND(F9>=0.2,G9>=0.2),"3bet/call",IF(F9>=G9,"3bet","Call"))) -> 3bet/call
A10: CO | B10: T8s | C10: =INDEX(Folds_lidos!$D$5:$D$173,MATCH($B10,Folds_lidos!$A$5:$A$173,0)) -> 0 | D10: =INDEX(Folds_lidos!$E$5:$E$173,MATCH($B10,Folds_lidos!$A$5:$A$173,0)) -> 3 | E10: =C10+D10 -> 3 | F10: =INDEX(Maos_por_spot!$F$5:$F$173,MATCH($B10,Maos_por_spot!$A$5:$A$173,0)) -> 0.35 | G10: =INDEX(Maos_por_spot!$G$5:$G$173,MATCH($B10,Maos_por_spot!$A$5:$A$173,0)) -> 0.1 | H10: =INDEX(Maos_por_spot!$H$5:$H$173,MATCH($B10,Maos_por_spot!$A$5:$A$173,0)) -> 0.45 | I10: =IF(H10<0.2,"Fold",IF(AND(F10>=0.2,G10>=0.2),"3bet/call",IF(F10>=G10,"3bet","Call"))) -> 3bet
A11: BTN | B11: A8o | C11: =INDEX(Folds_lidos!$F$5:$F$173,MATCH($B11,Folds_lidos!$A$5:$A$173,0)) -> 16 | D11: =INDEX(Folds_lidos!$G$5:$G$173,MATCH($B11,Folds_lidos!$A$5:$A$173,0)) -> 11 | E11: =C11+D11 -> 27 | F11: =INDEX(Maos_por_spot!$J$5:$J$173,MATCH($B11,Maos_por_spot!$A$5:$A$173,0)) -> 0.4 | G11: =INDEX(Maos_por_spot!$K$5:$K$173,MATCH($B11,Maos_por_spot!$A$5:$A$173,0)) -> 0 | H11: =INDEX(Maos_por_spot!$L$5:$L$173,MATCH($B11,Maos_por_spot!$A$5:$A$173,0)) -> 0.4 | I11: =IF(H11<0.2,"Fold",IF(AND(F11>=0.2,G11>=0.2),"3bet/call",IF(F11>=G11,"3bet","Call"))) -> 3bet
A12: BTN | B12: QJo | C12: =INDEX(Folds_lidos!$F$5:$F$173,MATCH($B12,Folds_lidos!$A$5:$A$173,0)) -> 3 | D12: =INDEX(Folds_lidos!$G$5:$G$173,MATCH($B12,Folds_lidos!$A$5:$A$173,0)) -> 5 | E12: =C12+D12 -> 8 | F12: =INDEX(Maos_por_spot!$J$5:$J$173,MATCH($B12,Maos_por_spot!$A$5:$A$173,0)) -> 0.45 | G12: =INDEX(Maos_por_spot!$K$5:$K$173,MATCH($B12,Maos_por_spot!$A$5:$A$173,0)) -> 0.55 | H12: =INDEX(Maos_por_spot!$L$5:$L$173,MATCH($B12,Maos_por_spot!$A$5:$A$173,0)) -> 1 | I12: =IF(H12<0.2,"Fold",IF(AND(F12>=0.2,G12>=0.2),"3bet/call",IF(F12>=G12,"3bet","Call"))) -> 3bet/call
A13: BTN | B13: KTo | C13: =INDEX(Folds_lidos!$F$5:$F$173,MATCH($B13,Folds_lidos!$A$5:$A$173,0)) -> 1 | D13: =INDEX(Folds_lidos!$G$5:$G$173,MATCH($B13,Folds_lidos!$A$5:$A$173,0)) -> 7 | E13: =C13+D13 -> 8 | F13: =INDEX(Maos_por_spot!$J$5:$J$173,MATCH($B13,Maos_por_spot!$A$5:$A$173,0)) -> 0.4 | G13: =INDEX(Maos_por_spot!$K$5:$K$173,MATCH($B13,Maos_por_spot!$A$5:$A$173,0)) -> 0.6 | H13: =INDEX(Maos_por_spot!$L$5:$L$173,MATCH($B13,Maos_por_spot!$A$5:$A$173,0)) -> 1 | I13: =IF(H13<0.2,"Fold",IF(AND(F13>=0.2,G13>=0.2),"3bet/call",IF(F13>=G13,"3bet","Call"))) -> 3bet/call
A14: BTN | B14: A9o | C14: =INDEX(Folds_lidos!$F$5:$F$173,MATCH($B14,Folds_lidos!$A$5:$A$173,0)) -> 5 | D14: =INDEX(Folds_lidos!$G$5:$G$173,MATCH($B14,Folds_lidos!$A$5:$A$173,0)) -> 3 | E14: =C14+D14 -> 8 | F14: =INDEX(Maos_por_spot!$J$5:$J$173,MATCH($B14,Maos_por_spot!$A$5:$A$173,0)) -> 0.75 | G14: =INDEX(Maos_por_spot!$K$5:$K$173,MATCH($B14,Maos_por_spot!$A$5:$A$173,0)) -> 0.25 | H14: =INDEX(Maos_por_spot!$L$5:$L$173,MATCH($B14,Maos_por_spot!$A$5:$A$173,0)) -> 1 | I14: =IF(H14<0.2,"Fold",IF(AND(F14>=0.2,G14>=0.2),"3bet/call",IF(F14>=G14,"3bet","Call"))) -> 3bet/call
A15: BTN | B15: Q8s | C15: =INDEX(Folds_lidos!$F$5:$F$173,MATCH($B15,Folds_lidos!$A$5:$A$173,0)) -> 3 | D15: =INDEX(Folds_lidos!$G$5:$G$173,MATCH($B15,Folds_lidos!$A$5:$A$173,0)) -> 4 | E15: =C15+D15 -> 7 | F15: =INDEX(Maos_por_spot!$J$5:$J$173,MATCH($B15,Maos_por_spot!$A$5:$A$173,0)) -> 0.85 | G15: =INDEX(Maos_por_spot!$K$5:$K$173,MATCH($B15,Maos_por_spot!$A$5:$A$173,0)) -> 0.15 | H15: =INDEX(Maos_por_spot!$L$5:$L$173,MATCH($B15,Maos_por_spot!$A$5:$A$173,0)) -> 1 | I15: =IF(H15<0.2,"Fold",IF(AND(F15>=0.2,G15>=0.2),"3bet/call",IF(F15>=G15,"3bet","Call"))) -> 3bet
A16: BTN | B16: 87s | C16: =INDEX(Folds_lidos!$F$5:$F$173,MATCH($B16,Folds_lidos!$A$5:$A$173,0)) -> 3 | D16: =INDEX(Folds_lidos!$G$5:$G$173,MATCH($B16,Folds_lidos!$A$5:$A$173,0)) -> 4 | E16: =C16+D16 -> 7 | F16: =INDEX(Maos_por_spot!$J$5:$J$173,MATCH($B16,Maos_por_spot!$A$5:$A$173,0)) -> 0.2 | G16: =INDEX(Maos_por_spot!$K$5:$K$173,MATCH($B16,Maos_por_spot!$A$5:$A$173,0)) -> 0.8 | H16: =INDEX(Maos_por_spot!$L$5:$L$173,MATCH($B16,Maos_por_spot!$A$5:$A$173,0)) -> 1 | I16: =IF(H16<0.2,"Fold",IF(AND(F16>=0.2,G16>=0.2),"3bet/call",IF(F16>=G16,"3bet","Call"))) -> 3bet/call
A17: BTN | B17: T8s | C17: =INDEX(Folds_lidos!$F$5:$F$173,MATCH($B17,Folds_lidos!$A$5:$A$173,0)) -> 3 | D17: =INDEX(Folds_lidos!$G$5:$G$173,MATCH($B17,Folds_lidos!$A$5:$A$173,0)) -> 3 | E17: =C17+D17 -> 6 | F17: =INDEX(Maos_por_spot!$J$5:$J$173,MATCH($B17,Maos_por_spot!$A$5:$A$173,0)) -> 0.2 | G17: =INDEX(Maos_por_spot!$K$5:$K$173,MATCH($B17,Maos_por_spot!$A$5:$A$173,0)) -> 0.8 | H17: =INDEX(Maos_por_spot!$L$5:$L$173,MATCH($B17,Maos_por_spot!$A$5:$A$173,0)) -> 1 | I17: =IF(H17<0.2,"Fold",IF(AND(F17>=0.2,G17>=0.2),"3bet/call",IF(F17>=G17,"3bet","Call"))) -> 3bet/call
A18: BTN | B18: K6s | C18: =INDEX(Folds_lidos!$F$5:$F$173,MATCH($B18,Folds_lidos!$A$5:$A$173,0)) -> 2 | D18: =INDEX(Folds_lidos!$G$5:$G$173,MATCH($B18,Folds_lidos!$A$5:$A$173,0)) -> 3 | E18: =C18+D18 -> 5 | F18: =INDEX(Maos_por_spot!$J$5:$J$173,MATCH($B18,Maos_por_spot!$A$5:$A$173,0)) -> 0.35 | G18: =INDEX(Maos_por_spot!$K$5:$K$173,MATCH($B18,Maos_por_spot!$A$5:$A$173,0)) -> 0.45 | H18: =INDEX(Maos_por_spot!$L$5:$L$173,MATCH($B18,Maos_por_spot!$A$5:$A$173,0)) -> 0.8 | I18: =IF(H18<0.2,"Fold",IF(AND(F18>=0.2,G18>=0.2),"3bet/call",IF(F18>=G18,"3bet","Call"))) -> 3bet/call
A19: BTN | B19: 97s | C19: =INDEX(Folds_lidos!$F$5:$F$173,MATCH($B19,Folds_lidos!$A$5:$A$173,0)) -> 1 | D19: =INDEX(Folds_lidos!$G$5:$G$173,MATCH($B19,Folds_lidos!$A$5:$A$173,0)) -> 4 | E19: =C19+D19 -> 5 | F19: =INDEX(Maos_por_spot!$J$5:$J$173,MATCH($B19,Maos_por_spot!$A$5:$A$173,0)) -> 0.3 | G19: =INDEX(Maos_por_spot!$K$5:$K$173,MATCH($B19,Maos_por_spot!$A$5:$A$173,0)) -> 0 | H19: =INDEX(Maos_por_spot!$L$5:$L$173,MATCH($B19,Maos_por_spot!$A$5:$A$173,0)) -> 0.3 | I19: =IF(H19<0.2,"Fold",IF(AND(F19>=0.2,G19>=0.2),"3bet/call",IF(F19>=G19,"3bet","Call"))) -> 3bet
A20: BTN | B20: K7s | C20: =INDEX(Folds_lidos!$F$5:$F$173,MATCH($B20,Folds_lidos!$A$5:$A$173,0)) -> 3 | D20: =INDEX(Folds_lidos!$G$5:$G$173,MATCH($B20,Folds_lidos!$A$5:$A$173,0)) -> 1 | E20: =C20+D20 -> 4 | F20: =INDEX(Maos_por_spot!$J$5:$J$173,MATCH($B20,Maos_por_spot!$A$5:$A$173,0)) -> 0.65 | G20: =INDEX(Maos_por_spot!$K$5:$K$173,MATCH($B20,Maos_por_spot!$A$5:$A$173,0)) -> 0.35 | H20: =INDEX(Maos_por_spot!$L$5:$L$173,MATCH($B20,Maos_por_spot!$A$5:$A$173,0)) -> 1 | I20: =IF(H20<0.2,"Fold",IF(AND(F20>=0.2,G20>=0.2),"3bet/call",IF(F20>=G20,"3bet","Call"))) -> 3bet/call
A21: BTN | B21: KJo | C21: =INDEX(Folds_lidos!$F$5:$F$173,MATCH($B21,Folds_lidos!$A$5:$A$173,0)) -> 2 | D21: =INDEX(Folds_lidos!$G$5:$G$173,MATCH($B21,Folds_lidos!$A$5:$A$173,0)) -> 2 | E21: =C21+D21 -> 4 | F21: =INDEX(Maos_por_spot!$J$5:$J$173,MATCH($B21,Maos_por_spot!$A$5:$A$173,0)) -> 0.2 | G21: =INDEX(Maos_por_spot!$K$5:$K$173,MATCH($B21,Maos_por_spot!$A$5:$A$173,0)) -> 0.8 | H21: =INDEX(Maos_por_spot!$L$5:$L$173,MATCH($B21,Maos_por_spot!$A$5:$A$173,0)) -> 1 | I21: =IF(H21<0.2,"Fold",IF(AND(F21>=0.2,G21>=0.2),"3bet/call",IF(F21>=G21,"3bet","Call"))) -> 3bet/call
A22: BTN | B22: 22 | C22: =INDEX(Folds_lidos!$F$5:$F$173,MATCH($B22,Folds_lidos!$A$5:$A$173,0)) -> 2 | D22: =INDEX(Folds_lidos!$G$5:$G$173,MATCH($B22,Folds_lidos!$A$5:$A$173,0)) -> 2 | E22: =C22+D22 -> 4 | F22: =INDEX(Maos_por_spot!$J$5:$J$173,MATCH($B22,Maos_por_spot!$A$5:$A$173,0)) -> 0 | G22: =INDEX(Maos_por_spot!$K$5:$K$173,MATCH($B22,Maos_por_spot!$A$5:$A$173,0)) -> 1 | H22: =INDEX(Maos_por_spot!$L$5:$L$173,MATCH($B22,Maos_por_spot!$A$5:$A$173,0)) -> 1 | I22: =IF(H22<0.2,"Fold",IF(AND(F22>=0.2,G22>=0.2),"3bet/call",IF(F22>=G22,"3bet","Call"))) -> Call
... A26: BTN | B26: 33 | C26: =INDEX(Folds_lidos!$F$5:$F$173,MATCH($B26,Folds_lidos!$A$5:$A$173,0)) -> 0 | D26: =INDEX(Folds_lidos!$G$5:$G$173,MATCH($B26,Folds_lidos!$A$5:$A$173,0)) -> 3 | E26: =C26+D26 -> 3 | F26: =INDEX(Maos_por_spot!$J$5:$J$173,MATCH($B26,Maos_por_spot!$A$5:$A$173,0)) -> 0 | G26: =INDEX(Maos_por_spot!$K$5:$K$173,MATCH($B26,Maos_por_spot!$A$5:$A$173,0)) -> 1 | H26: =INDEX(Maos_por_spot!$L$5:$L$173,MATCH($B26,Maos_por_spot!$A$5:$A$173,0)) -> 1 | I26: =IF(H26<0.2,"Fold",IF(AND(F26>=0.2,G26>=0.2),"3bet/call",IF(F26>=G26,"3bet","Call"))) -> Call
A27: SB | B27: A7o | C27: =INDEX(Folds_lidos!$H$5:$H$173,MATCH($B27,Folds_lidos!$A$5:$A$173,0)) -> 7 | D27: =INDEX(Folds_lidos!$I$5:$I$173,MATCH($B27,Folds_lidos!$A$5:$A$173,0)) -> 6 | E27: =C27+D27 -> 13 | F27: =INDEX(Maos_por_spot!$N$5:$N$173,MATCH($B27,Maos_por_spot!$A$5:$A$173,0)) -> 0.6 | G27: =INDEX(Maos_por_spot!$O$5:$O$173,MATCH($B27,Maos_por_spot!$A$5:$A$173,0)) -> 0 | H27: =INDEX(Maos_por_spot!$P$5:$P$173,MATCH($B27,Maos_por_spot!$A$5:$A$173,0)) -> 0.6 | I27: =IF(H27<0.2,"Fold",IF(AND(F27>=0.2,G27>=0.2),"3bet/call",IF(F27>=G27,"3bet","Call"))) -> 3bet
A28: SB | B28: KTo | C28: =INDEX(Folds_lidos!$H$5:$H$173,MATCH($B28,Folds_lidos!$A$5:$A$173,0)) -> 5 | D28: =INDEX(Folds_lidos!$I$5:$I$173,MATCH($B28,Folds_lidos!$A$5:$A$173,0)) -> 7 | E28: =C28+D28 -> 12 | F28: =INDEX(Maos_por_spot!$N$5:$N$173,MATCH($B28,Maos_por_spot!$A$5:$A$173,0)) -> 0.55 | G28: =INDEX(Maos_por_spot!$O$5:$O$173,MATCH($B28,Maos_por_spot!$A$5:$A$173,0)) -> 0.45 | H28: =INDEX(Maos_por_spot!$P$5:$P$173,MATCH($B28,Maos_por_spot!$A$5:$A$173,0)) -> 1 | I28: =IF(H28<0.2,"Fold",IF(AND(F28>=0.2,G28>=0.2),"3bet/call",IF(F28>=G28,"3bet","Call"))) -> 3bet/call
A29: SB | B29: A9o | C29: =INDEX(Folds_lidos!$H$5:$H$173,MATCH($B29,Folds_lidos!$A$5:$A$173,0)) -> 5 | D29: =INDEX(Folds_lidos!$I$5:$I$173,MATCH($B29,Folds_lidos!$A$5:$A$173,0)) -> 4 | E29: =C29+D29 -> 9 | F29: =INDEX(Maos_por_spot!$N$5:$N$173,MATCH($B29,Maos_por_spot!$A$5:$A$173,0)) -> 1 | G29: =INDEX(Maos_por_spot!$O$5:$O$173,MATCH($B29,Maos_por_spot!$A$5:$A$173,0)) -> 0 | H29: =INDEX(Maos_por_spot!$P$5:$P$173,MATCH($B29,Maos_por_spot!$A$5:$A$173,0)) -> 1 | I29: =IF(H29<0.2,"Fold",IF(AND(F29>=0.2,G29>=0.2),"3bet/call",IF(F29>=G29,"3bet","Call"))) -> 3bet
A30: SB | B30: 54s | C30: =INDEX(Folds_lidos!$H$5:$H$173,MATCH($B30,Folds_lidos!$A$5:$A$173,0)) -> 4 | D30: =INDEX(Folds_lidos!$I$5:$I$173,MATCH($B30,Folds_lidos!$A$5:$A$173,0)) -> 5 | E30: =C30+D30 -> 9 | F30: =INDEX(Maos_por_spot!$N$5:$N$173,MATCH($B30,Maos_por_spot!$A$5:$A$173,0)) -> 0 | G30: =INDEX(Maos_por_spot!$O$5:$O$173,MATCH($B30,Maos_por_spot!$A$5:$A$173,0)) -> 0.45 | H30: =INDEX(Maos_por_spot!$P$5:$P$173,MATCH($B30,Maos_por_spot!$A$5:$A$173,0)) -> 0.45 | I30: =IF(H30<0.2,"Fold",IF(AND(F30>=0.2,G30>=0.2),"3bet/call",IF(F30>=G30,"3bet","Call"))) -> Call
A31: SB | B31: JTo | C31: =INDEX(Folds_lidos!$H$5:$H$173,MATCH($B31,Folds_lidos!$A$5:$A$173,0)) -> 4 | D31: =INDEX(Folds_lidos!$I$5:$I$173,MATCH($B31,Folds_lidos!$A$5:$A$173,0)) -> 4 | E31: =C31+D31 -> 8 | F31: =INDEX(Maos_por_spot!$N$5:$N$173,MATCH($B31,Maos_por_spot!$A$5:$A$173,0)) -> 0.35 | G31: =INDEX(Maos_por_spot!$O$5:$O$173,MATCH($B31,Maos_por_spot!$A$5:$A$173,0)) -> 0.65 | H31: =INDEX(Maos_por_spot!$P$5:$P$173,MATCH($B31,Maos_por_spot!$A$5:$A$173,0)) -> 1 | I31: =IF(H31<0.2,"Fold",IF(AND(F31>=0.2,G31>=0.2),"3bet/call",IF(F31>=G31,"3bet","Call"))) -> 3bet/call
A32: SB | B32: QTo | C32: =INDEX(Folds_lidos!$H$5:$H$173,MATCH($B32,Folds_lidos!$A$5:$A$173,0)) -> 3 | D32: =INDEX(Folds_lidos!$I$5:$I$173,MATCH($B32,Folds_lidos!$A$5:$A$173,0)) -> 4 | E32: =C32+D32 -> 7 | F32: =INDEX(Maos_por_spot!$N$5:$N$173,MATCH($B32,Maos_por_spot!$A$5:$A$173,0)) -> 0.35 | G32: =INDEX(Maos_por_spot!$O$5:$O$173,MATCH($B32,Maos_por_spot!$A$5:$A$173,0)) -> 0.65 | H32: =INDEX(Maos_por_spot!$P$5:$P$173,MATCH($B32,Maos_por_spot!$A$5:$A$173,0)) -> 1 | I32: =IF(H32<0.2,"Fold",IF(AND(F32>=0.2,G32>=0.2),"3bet/call",IF(F32>=G32,"3bet","Call"))) -> 3bet/call
A33: SB | B33: Q7s | C33: =INDEX(Folds_lidos!$H$5:$H$173,MATCH($B33,Folds_lidos!$A$5:$A$173,0)) -> 1 | D33: =INDEX(Folds_lidos!$I$5:$I$173,MATCH($B33,Folds_lidos!$A$5:$A$173,0)) -> 5 | E33: =C33+D33 -> 6 | F33: =INDEX(Maos_por_spot!$N$5:$N$173,MATCH($B33,Maos_por_spot!$A$5:$A$173,0)) -> 0.75 | G33: =INDEX(Maos_por_spot!$O$5:$O$173,MATCH($B33,Maos_por_spot!$A$5:$A$173,0)) -> 0.25 | H33: =INDEX(Maos_por_spot!$P$5:$P$173,MATCH($B33,Maos_por_spot!$A$5:$A$173,0)) -> 1 | I33: =IF(H33<0.2,"Fold",IF(AND(F33>=0.2,G33>=0.2),"3bet/call",IF(F33>=G33,"3bet","Call"))) -> 3bet/call
A34: SB | B34: A8o | C34: =INDEX(Folds_lidos!$H$5:$H$173,MATCH($B34,Folds_lidos!$A$5:$A$173,0)) -> 1 | D34: =INDEX(Folds_lidos!$I$5:$I$173,MATCH($B34,Folds_lidos!$A$5:$A$173,0)) -> 5 | E34: =C34+D34 -> 6 | F34: =INDEX(Maos_por_spot!$N$5:$N$173,MATCH($B34,Maos_por_spot!$A$5:$A$173,0)) -> 0.7 | G34: =INDEX(Maos_por_spot!$O$5:$O$173,MATCH($B34,Maos_por_spot!$A$5:$A$173,0)) -> 0.3 | H34: =INDEX(Maos_por_spot!$P$5:$P$173,MATCH($B34,Maos_por_spot!$A$5:$A$173,0)) -> 1 | I34: =IF(H34<0.2,"Fold",IF(AND(F34>=0.2,G34>=0.2),"3bet/call",IF(F34>=G34,"3bet","Call"))) -> 3bet/call
A35: SB | B35: K5s | C35: =INDEX(Folds_lidos!$H$5:$H$173,MATCH($B35,Folds_lidos!$A$5:$A$173,0)) -> 1 | D35: =INDEX(Folds_lidos!$I$5:$I$173,MATCH($B35,Folds_lidos!$A$5:$A$173,0)) -> 4 | E35: =C35+D35 -> 5 | F35: =INDEX(Maos_por_spot!$N$5:$N$173,MATCH($B35,Maos_por_spot!$A$5:$A$173,0)) -> 0.25 | G35: =INDEX(Maos_por_spot!$O$5:$O$173,MATCH($B35,Maos_por_spot!$A$5:$A$173,0)) -> 0.75 | H35: =INDEX(Maos_por_spot!$P$5:$P$173,MATCH($B35,Maos_por_spot!$A$5:$A$173,0)) -> 1 | I35: =IF(H35<0.2,"Fold",IF(AND(F35>=0.2,G35>=0.2),"3bet/call",IF(F35>=G35,"3bet","Call"))) -> 3bet/call
A36: SB | B36: K4s | C36: =INDEX(Folds_lidos!$H$5:$H$173,MATCH($B36,Folds_lidos!$A$5:$A$173,0)) -> 4 | D36: =INDEX(Folds_lidos!$I$5:$I$173,MATCH($B36,Folds_lidos!$A$5:$A$173,0)) -> 1 | E36: =C36+D36 -> 5 | F36: =INDEX(Maos_por_spot!$N$5:$N$173,MATCH($B36,Maos_por_spot!$A$5:$A$173,0)) -> 0.2 | G36: =INDEX(Maos_por_spot!$O$5:$O$173,MATCH($B36,Maos_por_spot!$A$5:$A$173,0)) -> 0.8 | H36: =INDEX(Maos_por_spot!$P$5:$P$173,MATCH($B36,Maos_por_spot!$A$5:$A$173,0)) -> 1 | I36: =IF(H36<0.2,"Fold",IF(AND(F36>=0.2,G36>=0.2),"3bet/call",IF(F36>=G36,"3bet","Call"))) -> 3bet/call
A37: SB | B37: 87s | C37: =INDEX(Folds_lidos!$H$5:$H$173,MATCH($B37,Folds_lidos!$A$5:$A$173,0)) -> 4 | D37: =INDEX(Folds_lidos!$I$5:$I$173,MATCH($B37,Folds_lidos!$A$5:$A$173,0)) -> 1 | E37: =C37+D37 -> 5 | F37: =INDEX(Maos_por_spot!$N$5:$N$173,MATCH($B37,Maos_por_spot!$A$5:$A$173,0)) -> 0.15 | G37: =INDEX(Maos_por_spot!$O$5:$O$173,MATCH($B37,Maos_por_spot!$A$5:$A$173,0)) -> 0.85 | H37: =INDEX(Maos_por_spot!$P$5:$P$173,MATCH($B37,Maos_por_spot!$A$5:$A$173,0)) -> 1 | I37: =IF(H37<0.2,"Fold",IF(AND(F37>=0.2,G37>=0.2),"3bet/call",IF(F37>=G37,"3bet","Call"))) -> Call
A38: SB | B38: 33 | C38: =INDEX(Folds_lidos!$H$5:$H$173,MATCH($B38,Folds_lidos!$A$5:$A$173,0)) -> 1 | D38: =INDEX(Folds_lidos!$I$5:$I$173,MATCH($B38,Folds_lidos!$A$5:$A$173,0)) -> 4 | E38: =C38+D38 -> 5 | F38: =INDEX(Maos_por_spot!$N$5:$N$173,MATCH($B38,Maos_por_spot!$A$5:$A$173,0)) -> 0 | G38: =INDEX(Maos_por_spot!$O$5:$O$173,MATCH($B38,Maos_por_spot!$A$5:$A$173,0)) -> 1 | H38: =INDEX(Maos_por_spot!$P$5:$P$173,MATCH($B38,Maos_por_spot!$A$5:$A$173,0)) -> 1 | I38: =IF(H38<0.2,"Fold",IF(AND(F38>=0.2,G38>=0.2),"3bet/call",IF(F38>=G38,"3bet","Call"))) -> Call
... A47: SB | B47: 22 | C47: =INDEX(Folds_lidos!$H$5:$H$173,MATCH($B47,Folds_lidos!$A$5:$A$173,0)) -> 0 | D47: =INDEX(Folds_lidos!$I$5:$I$173,MATCH($B47,Folds_lidos!$A$5:$A$173,0)) -> 3 | E47: =C47+D47 -> 3 | F47: =INDEX(Maos_por_spot!$N$5:$N$173,MATCH($B47,Maos_por_spot!$A$5:$A$173,0)) -> 0 | G47: =INDEX(Maos_por_spot!$O$5:$O$173,MATCH($B47,Maos_por_spot!$A$5:$A$173,0)) -> 1 | H47: =INDEX(Maos_por_spot!$P$5:$P$173,MATCH($B47,Maos_por_spot!$A$5:$A$173,0)) -> 1 | I47: =IF(H47<0.2,"Fold",IF(AND(F47>=0.2,G47>=0.2),"3bet/call",IF(F47>=G47,"3bet","Call"))) -> Call

Sheet Checklist_folds
A1: Checklist: mãos que o solver defende e você pode estar foldando
A2: Só aparecem as mãos que o solver continua em 30% ou mais. Preencha "Vezes foldada" com o número do seu HUD (amarelo).
A3: Legenda: "Vezes foldada" vem da aba Folds_total (todas as semanas). Peso = foldada × continua do solver. "Revisar" aparece quando o solver defende a mão em 80% ou mais e os folds chegam ao mínimo da célula amarela D4. Amarelo: mínimo e observações.
A4: Mínimo de folds para marcar "Revisar": | D4: 7
A5: Posição | B5: Mão | C5: Continua (solver) | D5: Ação do solver | E5: Vezes foldada (total das semanas) | F5: Peso | G5: Prioridade | H5: Observação
A6: HJ | B6: AA | C6: =INDEX(Maos_por_spot!$D$5:$D$173,MATCH($B6,Maos_por_spot!$A$5:$A$173,0)) -> 1 | D6: =INDEX(Maos_por_spot!$E$5:$E$173,MATCH($B6,Maos_por_spot!$A$5:$A$173,0)) -> 3bet | E6: =INDEX(Folds_total!$B$5:$B$173,MATCH($B6,Folds_total!$A$5:$A$173,0)) -> 0 | F6: =IF(E6="","",E6*C6) -> 0 | G6: =IF(E6="","",IF(AND(C6>=0.8,E6>=$D$4),"Revisar: o solver quase sempre defende",""))
A7: HJ | B7: AKs | C7: =INDEX(Maos_por_spot!$D$5:$D$173,MATCH($B7,Maos_por_spot!$A$5:$A$173,0)) -> 1 | D7: =INDEX(Maos_por_spot!$E$5:$E$173,MATCH($B7,Maos_por_spot!$A$5:$A$173,0)) -> 3bet | E7: =INDEX(Folds_total!$B$5:$B$173,MATCH($B7,Folds_total!$A$5:$A$173,0)) -> 0 | F7: =IF(E7="","",E7*C7) -> 0 | G7: =IF(E7="","",IF(AND(C7>=0.8,E7>=$D$4),"Revisar: o solver quase sempre defende",""))
